Workbook

Sheet Merchants
A1: merchant_id | B1: merchant_name | C1: category | D1: region
A2: 1 | B2: Merchant_001 | C2: ecommerce | D2: South
A3: 2 | B3: Merchant_002 | C3: grocery | D3: West
A4: 3 | B4: Merchant_003 | C4: grocery | D4: East
A5: 4 | B5: Merchant_004 | C5: ecommerce | D5: East
A6: 5 | B6: Merchant_005 | C6: recharge | D6: South
A7: 6 | B7: Merchant_006 | C7: food_delivery | D7: South
A8: 7 | B8: Merchant_007 | C8: food_delivery | D8: East
A9: 8 | B9: Merchant_008 | C9: food_delivery | D9: North
A10: 9 | B10: Merchant_009 | C10: ecommerce | D10: North
A11: 10 | B11: Merchant_010 | C11: grocery | D11: West
A12: 11 | B12: Merchant_011 | C12: ecommerce | D12: North
A13: 12 | B13: Merchant_012 | C13: ecommerce | D13: East
... A41: 40 | B41: Merchant_040 | C41: entertainment | D41: South

Sheet Fee_Tiers
A1: Chosen MDR-style fee percentages (illustrative): UPI=0.0%, Wallet=1.5%, Card=1.8%, Netbanking=1.2%
A2: Payment Method | B2: UPI | C2: Wallet | D2: Card | E2: Netbanking
A3: Fee % (MDR-style) | B3: 0 | C3: 0.015 | D3: 0.018 | E3: 0.012

Sheet Merchant_Day_Analysis
A1: PIVOT-STYLE AGGREGATION (static values, computed with pandas groupby by merchant_id x day — NOT a live Excel PivotTable, since openpyxl cannot create live PivotTable objects).
A2: EXACT RULE: classification = "High-Value Merchant Day" when daily_total_inr > 5000 AND region <> "East"; otherwise "Normal".
A4: merchant_day_key | B4: merchant_id | C4: merchant_name | D4: region | E4: txn_date | F4: daily_total_inr | G4: classification (nested IF/AND)
A5: 1_2026-01-05 | B5: 1 | C5: Merchant_001 | D5: South | E5: 46027 | F5: 1499 | G5: =IF(AND(F5>5000,D5<>"East"),"High-Value Merchant Day","Normal")
A6: 1_2026-01-06 | B6: 1 | C6: Merchant_001 | D6: South | E6: 46028 | F6: 149 | G6: =IF(AND(F6>5000,D6<>"East"),"High-Value Merchant Day","Normal")
A7: 1_2026-01-09 | B7: 1 | C7: Merchant_001 | D7: South | E7: 46031 | F7: 5048 | G7: =IF(AND(F7>5000,D7<>"East"),"High-Value Merchant Day","Normal")
A8: 1_2026-01-11 | B8: 1 | C8: Merchant_001 | D8: South | E8: 46033 | F8: 299 | G8: =IF(AND(F8>5000,D8<>"East"),"High-Value Merchant Day","Normal")
A9: 1_2026-01-12 | B9: 1 | C9: Merchant_001 | D9: South | E9: 46034 | F9: 149 | G9: =IF(AND(F9>5000,D9<>"East"),"High-Value Merchant Day","Normal")
A10: 1_2026-01-17 | B10: 1 | C10: Merchant_001 | D10: South | E10: 46039 | F10: 149 | G10: =IF(AND(F10>5000,D10<>"East"),"High-Value Merchant Day","Normal")
A11: 1_2026-01-23 | B11: 1 | C11: Merchant_001 | D11: South | E11: 46045 | F11: 3148 | G11: =IF(AND(F11>5000,D11<>"East"),"High-Value Merchant Day","Normal")
A12: 2_2026-01-07 | B12: 2 | C12: Merchant_002 | D12: West | E12: 46029 | F12: 499 | G12: =IF(AND(F12>5000,D12<>"East"),"High-Value Merchant Day","Normal")
A13: 2_2026-01-08 | B13: 2 | C13: Merchant_002 | D13: West | E13: 46030 | F13: 299 | G13: =IF(AND(F13>5000,D13<>"East"),"High-Value Merchant Day","Normal")
A14: 2_2026-01-12 | B14: 2 | C14: Merchant_002 | D14: West | E14: 46034 | F14: 348 | G14: =IF(AND(F14>5000,D14<>"East"),"High-Value Merchant Day","Normal")
A15: 2_2026-01-13 | B15: 2 | C15: Merchant_002 | D15: West | E15: 46035 | F15: 49 | G15: =IF(AND(F15>5000,D15<>"East"),"High-Value Merchant Day","Normal")
A16: 2_2026-01-15 | B16: 2 | C16: Merchant_002 | D16: West | E16: 46037 | F16: 1499 | G16: =IF(AND(F16>5000,D16<>"East"),"High-Value Merchant Day","Normal")
... A447: 40_2026-01-30 | B447: 40 | C447: Merchant_040 | D447: South | E447: 46052 | F447: 499 | G447: =IF(AND(F447>5000,D447<>"East"),"High-Value Merchant Day","Normal")

Sheet Transactions_View
A1: transaction_id | B1: user_id | C1: merchant_id | D1: transaction_time | E1: amount_inr | F1: payment_method | G1: status | H1: risk_score | I1: merchant_name (VLOOKUP) | J1: category (VLOOKUP) | K1: region (VLOOKUP) | L1: fee_pct (HLOOKUP) | M1: fee_amount_inr | N1: txn_date | O1: merchant_day_key | P1: day_classification (VLOOKUP link-back)
A2: TXN100000 | B2: 350 | C2: 16 | D2: 46051.467 | E2: 2999 | F2: Wallet | G2: captured | H2: 85 | I2: =IFERROR(VLOOKUP(C2,Merchants!$A$2:$D$41,2,FALSE),"Merchant not found") | J2: =IFERROR(VLOOKUP(C2,Merchants!$A$2:$D$41,3,FALSE),"Merchant not found") | K2: =IFERROR(VLOOKUP(C2,Merchants!$A$2:$D$41,4,FALSE),"Merchant not found") | L2: =HLOOKUP(F2,Fee_Tiers!$B$2:$E$3,2,FALSE) | M2: =E2*L2 | N2: 46051 | O2: =C2&"_"&TEXT(N2,"yyyy-mm-dd") | P2: =IFERROR(VLOOKUP(O2,Merchant_Day_Analysis!$A$5:$G$447,7,FALSE),"Not found")
A3: TXN100001 | B3: 287 | C3: 27 | D3: 46026.492 | E3: 49 | F3: UPI | G3: captured | H3: 79 | I3: =IFERROR(VLOOKUP(C3,Merchants!$A$2:$D$41,2,FALSE),"Merchant not found") | J3: =IFERROR(VLOOKUP(C3,Merchants!$A$2:$D$41,3,FALSE),"Merchant not found") | K3: =IFERROR(VLOOKUP(C3,Merchants!$A$2:$D$41,4,FALSE),"Merchant not found") | L3: =HLOOKUP(F3,Fee_Tiers!$B$2:$E$3,2,FALSE) | M3: =E3*L3 | N3: 46026 | O3: =C3&"_"&TEXT(N3,"yyyy-mm-dd") | P3: =IFERROR(VLOOKUP(O3,Merchant_Day_Analysis!$A$5:$G$447,7,FALSE),"Not found")
A4: TXN100002 | B4: 122 | C4: 11 | D4: 46046.208 | E4: 1499 | F4: Wallet | G4: captured | H4: 22 | I4: =IFERROR(VLOOKUP(C4,Merchants!$A$2:$D$41,2,FALSE),"Merchant not found") | J4: =IFERROR(VLOOKUP(C4,Merchants!$A$2:$D$41,3,FALSE),"Merchant not found") | K4: =IFERROR(VLOOKUP(C4,Merchants!$A$2:$D$41,4,FALSE),"Merchant not found") | L4: =HLOOKUP(F4,Fee_Tiers!$B$2:$E$3,2,FALSE) | M4: =E4*L4 | N4: 46046 | O4: =C4&"_"&TEXT(N4,"yyyy-mm-dd") | P4: =IFERROR(VLOOKUP(O4,Merchant_Day_Analysis!$A$5:$G$447,7,FALSE),"Not found")
A5: TXN100003 | B5: 92 | C5: 22 | D5: 46051.542 | E5: 49 | F5: Netbanking | G5: captured | H5: 100 | I5: =IFERROR(VLOOKUP(C5,Merchants!$A$2:$D$41,2,FALSE),"Merchant not found") | J5: =IFERROR(VLOOKUP(C5,Merchants!$A$2:$D$41,3,FALSE),"Merchant not found") | K5: =IFERROR(VLOOKUP(C5,Merchants!$A$2:$D$41,4,FALSE),"Merchant not found") | L5: =HLOOKUP(F5,Fee_Tiers!$B$2:$E$3,2,FALSE) | M5: =E5*L5 | N5: 46051 | O5: =C5&"_"&TEXT(N5,"yyyy-mm-dd") | P5: =IFERROR(VLOOKUP(O5,Merchant_Day_Analysis!$A$5:$G$447,7,FALSE),"Not found")
A6: TXN100004 | B6: 343 | C6: 16 | D6: 46052.577 | E6: 99 | F6: UPI | G6: captured | H6: 34 | I6: =IFERROR(VLOOKUP(C6,Merchants!$A$2:$D$41,2,FALSE),"Merchant not found") | J6: =IFERROR(VLOOKUP(C6,Merchants!$A$2:$D$41,3,FALSE),"Merchant not found") | K6: =IFERROR(VLOOKUP(C6,Merchants!$A$2:$D$41,4,FALSE),"Merchant not found") | L6: =HLOOKUP(F6,Fee_Tiers!$B$2:$E$3,2,FALSE) | M6: =E6*L6 | N6: 46052 | O6: =C6&"_"&TEXT(N6,"yyyy-mm-dd") | P6: =IFERROR(VLOOKUP(O6,Merchant_Day_Analysis!$A$5:$G$447,7,FALSE),"Not found")
A7: TXN100005 | B7: 196 | C7: 3 | D7: 46028.921 | E7: 99 | F7: UPI | G7: captured | H7: 60 | I7: =IFERROR(VLOOKUP(C7,Merchants!$A$2:$D$41,2,FALSE),"Merchant not found") | J7: =IFERROR(VLOOKUP(C7,Merchants!$A$2:$D$41,3,FALSE),"Merchant not found") | K7: =IFERROR(VLOOKUP(C7,Merchants!$A$2:$D$41,4,FALSE),"Merchant not found") | L7: =HLOOKUP(F7,Fee_Tiers!$B$2:$E$3,2,FALSE) | M7: =E7*L7 | N7: 46028 | O7: =C7&"_"&TEXT(N7,"yyyy-mm-dd") | P7: =IFERROR(VLOOKUP(O7,Merchant_Day_Analysis!$A$5:$G$447,7,FALSE),"Not found")
A8: TXN100006 | B8: 236 | C8: 23 | D8: 46030.286 | E8: 99 | F8: Wallet | G8: captured | H8: 39 | I8: =IFERROR(VLOOKUP(C8,Merchants!$A$2:$D$41,2,FALSE),"Merchant not found") | J8: =IFERROR(VLOOKUP(C8,Merchants!$A$2:$D$41,3,FALSE),"Merchant not found") | K8: =IFERROR(VLOOKUP(C8,Merchants!$A$2:$D$41,4,FALSE),"Merchant not found") | L8: =HLOOKUP(F8,Fee_Tiers!$B$2:$E$3,2,FALSE) | M8: =E8*L8 | N8: 46030 | O8: =C8&"_"&TEXT(N8,"yyyy-mm-dd") | P8: =IFERROR(VLOOKUP(O8,Merchant_Day_Analysis!$A$5:$G$447,7,FALSE),"Not found")
A9: TXN100007 | B9: 13 | C9: 13 | D9: 46049.301 | E9: 99 | F9: UPI | G9: captured | H9: 51 | I9: =IFERROR(VLOOKUP(C9,Merchants!$A$2:$D$41,2,FALSE),"Merchant not found") | J9: =IFERROR(VLOOKUP(C9,Merchants!$A$2:$D$41,3,FALSE),"Merchant not found") | K9: =IFERROR(VLOOKUP(C9,Merchants!$A$2:$D$41,4,FALSE),"Merchant not found") | L9: =HLOOKUP(F9,Fee_Tiers!$B$2:$E$3,2,FALSE) | M9: =E9*L9 | N9: 46049 | O9: =C9&"_"&TEXT(N9,"yyyy-mm-dd") | P9: =IFERROR(VLOOKUP(O9,Merchant_Day_Analysis!$A$5:$G$447,7,FALSE),"Not found")
A10: TXN100008 | B10: 36 | C10: 18 | D10: 46033.372 | E10: 799 | F10: UPI | G10: captured | H10: 44 | I10: =IFERROR(VLOOKUP(C10,Merchants!$A$2:$D$41,2,FALSE),"Merchant not found") | J10: =IFERROR(VLOOKUP(C10,Merchants!$A$2:$D$41,3,FALSE),"Merchant not found") | K10: =IFERROR(VLOOKUP(C10,Merchants!$A$2:$D$41,4,FALSE),"Merchant not found") | L10: =HLOOKUP(F10,Fee_Tiers!$B$2:$E$3,2,FALSE) | M10: =E10*L10 | N10: 46033 | O10: =C10&"_"&TEXT(N10,"yyyy-mm-dd") | P10: =IFERROR(VLOOKUP(O10,Merchant_Day_Analysis!$A$5:$G$447,7,FALSE),"Not found")
A11: TXN100009 | B11: 348 | C11: 35 | D11: 46043.684 | E11: 299 | F11: UPI | G11: captured | H11: 42 | I11: =IFERROR(VLOOKUP(C11,Merchants!$A$2:$D$41,2,FALSE),"Merchant not found") | J11: =IFERROR(VLOOKUP(C11,Merchants!$A$2:$D$41,3,FALSE),"Merchant not found") | K11: =IFERROR(VLOOKUP(C11,Merchants!$A$2:$D$41,4,FALSE),"Merchant not found") | L11: =HLOOKUP(F11,Fee_Tiers!$B$2:$E$3,2,FALSE) | M11: =E11*L11 | N11: 46043 | O11: =C11&"_"&TEXT(N11,"yyyy-mm-dd") | P11: =IFERROR(VLOOKUP(O11,Merchant_Day_Analysis!$A$5:$G$447,7,FALSE),"Not found")
A12: TXN100010 | B12: 134 | C12: 12 | D12: 46023.164 | E12: 49 | F12: UPI | G12: captured | H12: 74 | I12: =IFERROR(VLOOKUP(C12,Merchants!$A$2:$D$41,2,FALSE),"Merchant not found") | J12: =IFERROR(VLOOKUP(C12,Merchants!$A$2:$D$41,3,FALSE),"Merchant not found") | K12: =IFERROR(VLOOKUP(C12,Merchants!$A$2:$D$41,4,FALSE),"Merchant not found") | L12: =HLOOKUP(F12,Fee_Tiers!$B$2:$E$3,2,FALSE) | M12: =E12*L12 | N12: 46023 | O12: =C12&"_"&TEXT(N12,"yyyy-mm-dd") | P12: =IFERROR(VLOOKUP(O12,Merchant_Day_Analysis!$A$5:$G$447,7,FALSE),"Not found")
A13: TXN100011 | B13: 306 | C13: 28 | D13: 46031.046 | E13: 2999 | F13: Card | G13: failed | H13: 44 | I13: =IFERROR(VLOOKUP(C13,Merchants!$A$2:$D$41,2,FALSE),"Merchant not found") | J13: =IFERROR(VLOOKUP(C13,Merchants!$A$2:$D$41,3,FALSE),"Merchant not found") | K13: =IFERROR(VLOOKUP(C13,Merchants!$A$2:$D$41,4,FALSE),"Merchant not found") | L13: =HLOOKUP(F13,Fee_Tiers!$B$2:$E$3,2,FALSE) | M13: =E13*L13 | N13: 46031 | O13: =C13&"_"&TEXT(N13,"yyyy-mm-dd") | P13: =IFERROR(VLOOKUP(O13,Merchant_Day_Analysis!$A$5:$G$447,7,FALSE),"Not found")
... A548: TXN300031 | B548: 345 | C548: 12 | D548: 46045.377 | E548: 399 | F548: Card | G548: captured | H548: 69 | I548: =IFERROR(VLOOKUP(C548,Merchants!$A$2:$D$41,2,FALSE),"Merchant not found") | J548: =IFERROR(VLOOKUP(C548,Merchants!$A$2:$D$41,3,FALSE),"Merchant not found") | K548: =IFERROR(VLOOKUP(C548,Merchants!$A$2:$D$41,4,FALSE),"Merchant not found") | L548: =HLOOKUP(F548,Fee_Tiers!$B$2:$E$3,2,FALSE) | M548: =E548*L548 | N548: 46045 | O548: =C548&"_"&TEXT(N548,"yyyy-mm-dd") | P548: =IFERROR(VLOOKUP(O548,Merchant_Day_Analysis!$A$5:$G$447,7,FALSE),"Not found")

Sheet Merchant_Status_Pivot
A1: PIVOT-STYLE TABLES (static values, computed with pandas pivot_table/groupby — NOT live Excel PivotTables). See Transactions_View's Excel Table to build a live PivotTable in Excel yourself.
A3: Pivot A: SUM(amount_inr) by merchant_id x status
A4: merchant_id | B4: merchant_name | C4: captured | D4: failed | E4: chargeback
A5: 1 | B5: Merchant_001 | C5: 10142 | D5: 299 | E5: 0
A6: 2 | B6: Merchant_002 | C6: 3640 | D6: 0 | E6: 0
A7: 3 | B7: Merchant_003 | C7: 8084 | D7: 0 | E7: 149
A8: 4 | B8: Merchant_004 | C8: 6941 | D8: 0 | E8: 0
A9: 5 | B9: Merchant_005 | C9: 5340 | D9: 499 | E9: 0
A10: 6 | B10: Merchant_006 | C10: 6637 | D10: 0 | E10: 799
A11: 7 | B11: Merchant_007 | C11: 11638 | D11: 2297 | E11: 1999
A12: 8 | B12: Merchant_008 | C12: 7086 | D12: 299 | E12: 49
A13: 9 | B13: Merchant_009 | C13: 4485 | D13: 497 | E13: 0
A14: 10 | B14: Merchant_010 | C14: 7639 | D14: 399 | E14: 5048
A15: 11 | B15: Merchant_011 | C15: 9292 | D15: 1499 | E15: 149
A16: 12 | B16: Merchant_012 | C16: 9389 | D16: 998 | E16: 0
... A44: 40 | B44: Merchant_040 | C44: 3039 | D44: 548 | E44: 5148
A47: Pivot B: COUNT(transactions) by merchant_id x status
A48: merchant_id | B48: merchant_name | C48: captured | D48: failed | E48: chargeback
A49: 1 | B49: Merchant_001 | C49: 8 | D49: 1 | E49: 0
A50: 2 | B50: Merchant_002 | C50: 10 | D50: 0 | E50: 0
A51: 3 | B51: Merchant_003 | C51: 16 | D51: 0 | E51: 1
A52: 4 | B52: Merchant_004 | C52: 9 | D52: 0 | E52: 0
A53: 5 | B53: Merchant_005 | C53: 10 | D53: 1 | E53: 0
A54: 6 | B54: Merchant_006 | C54: 13 | D54: 0 | E54: 1
A55: 7 | B55: Merchant_007 | C55: 12 | D55: 3 | E55: 1
A56: 8 | B56: Merchant_008 | C56: 14 | D56: 1 | E56: 1
A57: 9 | B57: Merchant_009 | C57: 15 | D57: 3 | E57: 0
A58: 10 | B58: Merchant_010 | C58: 11 | D58: 1 | E58: 2
A59: 11 | B59: Merchant_011 | C59: 8 | D59: 1 | E59: 1
A60: 12 | B60: Merchant_012 | C60: 11 | D60: 2 | E60: 0
... A88: 40 | B88: Merchant_040 | C88: 11 | D88: 2 | E88: 2
A91: Comparison: unique days transacted vs. total transaction count (per merchant)
A92: merchant_id | B92: merchant_name | C92: unique_days_transacted | D92: total_transaction_count
A93: 16 | B93: Merchant_016 | C93: 15 | D93: 20
A94: 29 | B94: Merchant_029 | C94: 13 | D94: 19
A95: 37 | B95: Merchant_037 | C95: 16 | D95: 19
A96: 9 | B96: Merchant_009 | C96: 14 | D96: 18
A97: 3 | B97: Merchant_003 | C97: 13 | D97: 17
A98: 25 | B98: Merchant_025 | C98: 11 | D98: 17
A99: 30 | B99: Merchant_030 | C99: 13 | D99: 17
...
